from app.custom_exceptions.user_exception import UserNotFoundError